2025-04-17 03:03:08,595 - INFO - Loading Stanford Cars dataset...
2025-04-17 03:03:08,595 - INFO - Downloading Stanford Cars dataset from Kaggle...
2025-04-17 03:03:21,803 - ERROR - Error loading Stanford Cars dataset: HTTPSConnectionPool(host='www.kaggle.com', port=443): Max retries exceeded with url: /api/v1/datasets/view/jessicali9530/stanford-cars-dataset (Caused by ConnectTimeoutError(<urllib3.connection.HTTPSConnection object at 0x7fe6d34bd400>, 'Connection to www.kaggle.com timed out. (connect timeout=5)'))
2025-04-17 03:03:21,803 - ERROR - Failed to load dataset: HTTPSConnectionPool(host='www.kaggle.com', port=443): Max retries exceeded with url: /api/v1/datasets/view/jessicali9530/stanford-cars-dataset (Caused by ConnectTimeoutError(<urllib3.connection.HTTPSConnection object at 0x7fe6d34bd400>, 'Connection to www.kaggle.com timed out. (connect timeout=5)'))
Traceback (most recent call last):
  File "/home/lokmane-zed/anaconda3/lib/python3.12/site-packages/urllib3/connection.py", line 196, in _new_conn
    sock = connection.create_connection(
           ^^^^^^^^^^^^^^^^^^^^^^^^^^^^^
  File "/home/lokmane-zed/anaconda3/lib/python3.12/site-packages/urllib3/util/connection.py", line 85, in create_connection
    raise err
  File "/home/lokmane-zed/anaconda3/lib/python3.12/site-packages/urllib3/util/connection.py", line 73, in create_connection
    sock.connect(sa)
TimeoutError: timed out

The above exception was the direct cause of the following exception:

Traceback (most recent call last):
  File "/home/lokmane-zed/anaconda3/lib/python3.12/site-packages/urllib3/connectionpool.py", line 789, in urlopen
    response = self._make_request(
               ^^^^^^^^^^^^^^^^^^^
  File "/home/lokmane-zed/anaconda3/lib/python3.12/site-packages/urllib3/connectionpool.py", line 490, in _make_request
    raise new_e
  File "/home/lokmane-zed/anaconda3/lib/python3.12/site-packages/urllib3/connectionpool.py", line 466, in _make_request
    self._validate_conn(conn)
  File "/home/lokmane-zed/anaconda3/lib/python3.12/site-packages/urllib3/connectionpool.py", line 1095, in _validate_conn
    conn.connect()
  File "/home/lokmane-zed/anaconda3/lib/python3.12/site-packages/urllib3/connection.py", line 615, in connect
    self.sock = sock = self._new_conn()
                       ^^^^^^^^^^^^^^^^
  File "/home/lokmane-zed/anaconda3/lib/python3.12/site-packages/urllib3/connection.py", line 205, in _new_conn
    raise ConnectTimeoutError(
urllib3.exceptions.ConnectTimeoutError: (<urllib3.connection.HTTPSConnection object at 0x7fe6d34bd400>, 'Connection to www.kaggle.com timed out. (connect timeout=5)')

The above exception was the direct cause of the following exception:

Traceback (most recent call last):
  File "/home/lokmane-zed/anaconda3/lib/python3.12/site-packages/requests/adapters.py", line 667, in send
    resp = conn.urlopen(
           ^^^^^^^^^^^^^
  File "/home/lokmane-zed/anaconda3/lib/python3.12/site-packages/urllib3/connectionpool.py", line 843, in urlopen
    retries = retries.increment(
              ^^^^^^^^^^^^^^^^^^
  File "/home/lokmane-zed/anaconda3/lib/python3.12/site-packages/urllib3/util/retry.py", line 519, in increment
    raise MaxRetryError(_pool, url, reason) from reason  # type: ignore[arg-type]
    ^^^^^^^^^^^^^^^^^^^^^^^^^^^^^^^^^^^^^^^^^^^^^^^^^^^
urllib3.exceptions.MaxRetryError: HTTPSConnectionPool(host='www.kaggle.com', port=443): Max retries exceeded with url: /api/v1/datasets/view/jessicali9530/stanford-cars-dataset (Caused by ConnectTimeoutError(<urllib3.connection.HTTPSConnection object at 0x7fe6d34bd400>, 'Connection to www.kaggle.com timed out. (connect timeout=5)'))

During handling of the above exception, another exception occurred:

Traceback (most recent call last):
  File "/home/lokmane-zed/project/DzVisionAi/back-end/src/ai/train_vehicle_model.py", line 467, in <module>
    main()
  File "/home/lokmane-zed/project/DzVisionAi/back-end/src/ai/train_vehicle_model.py", line 405, in main
    image_paths, color_labels, make_labels = load_stanford_cars_dataset()
                                             ^^^^^^^^^^^^^^^^^^^^^^^^^^^^
  File "/home/lokmane-zed/project/DzVisionAi/back-end/src/ai/train_vehicle_model.py", line 106, in load_stanford_cars_dataset
    kaggle_path = kagglehub.dataset_download("jessicali9530/stanford-cars-dataset")
                  ^^^^^^^^^^^^^^^^^^^^^^^^^^^^^^^^^^^^^^^^^^^^^^^^^^^^^^^^^^^^^^^^^
  File "/home/lokmane-zed/anaconda3/lib/python3.12/site-packages/kagglehub/datasets.py", line 35, in dataset_download
    path, _ = registry.dataset_resolver(h, path, force_download=force_download)
              ^^^^^^^^^^^^^^^^^^^^^^^^^^^^^^^^^^^^^^^^^^^^^^^^^^^^^^^^^^^^^^^^^
  File "/home/lokmane-zed/anaconda3/lib/python3.12/site-packages/kagglehub/registry.py", line 28, in __call__
    return impl(*args, **kwargs)
           ^^^^^^^^^^^^^^^^^^^^^
  File "/home/lokmane-zed/anaconda3/lib/python3.12/site-packages/kagglehub/resolver.py", line 29, in __call__
    path, version = self._resolve(handle, path, force_download=force_download)
                    ^^^^^^^^^^^^^^^^^^^^^^^^^^^^^^^^^^^^^^^^^^^^^^^^^^^^^^^^^^
  File "/home/lokmane-zed/anaconda3/lib/python3.12/site-packages/kagglehub/http_resolver.py", line 107, in _resolve
    h = h.with_version(_get_current_version(api_client, h))
                       ^^^^^^^^^^^^^^^^^^^^^^^^^^^^^^^^^^^
  File "/home/lokmane-zed/anaconda3/lib/python3.12/site-packages/kagglehub/http_resolver.py", line 290, in _get_current_version
    json_response = api_client.get(_build_get_dataset_url_path(h), h)
                    ^^^^^^^^^^^^^^^^^^^^^^^^^^^^^^^^^^^^^^^^^^^^^^^^^
  File "/home/lokmane-zed/anaconda3/lib/python3.12/site-packages/kagglehub/clients.py", line 132, in get
    with requests.get(
         ^^^^^^^^^^^^^
  File "/home/lokmane-zed/anaconda3/lib/python3.12/site-packages/requests/api.py", line 73, in get
    return request("get", url, params=params, **kwargs)
           ^^^^^^^^^^^^^^^^^^^^^^^^^^^^^^^^^^^^^^^^^^^^
  File "/home/lokmane-zed/anaconda3/lib/python3.12/site-packages/requests/api.py", line 59, in request
    return session.request(method=method, url=url, **kwargs)
           ^^^^^^^^^^^^^^^^^^^^^^^^^^^^^^^^^^^^^^^^^^^^^^^^^
  File "/home/lokmane-zed/anaconda3/lib/python3.12/site-packages/requests/sessions.py", line 589, in request
    resp = self.send(prep, **send_kwargs)
           ^^^^^^^^^^^^^^^^^^^^^^^^^^^^^^
  File "/home/lokmane-zed/anaconda3/lib/python3.12/site-packages/requests/sessions.py", line 703, in send
    r = adapter.send(request, **kwargs)
        ^^^^^^^^^^^^^^^^^^^^^^^^^^^^^^^
  File "/home/lokmane-zed/anaconda3/lib/python3.12/site-packages/requests/adapters.py", line 688, in send
    raise ConnectTimeout(e, request=request)
requests.exceptions.ConnectTimeout: HTTPSConnectionPool(host='www.kaggle.com', port=443): Max retries exceeded with url: /api/v1/datasets/view/jessicali9530/stanford-cars-dataset (Caused by ConnectTimeoutError(<urllib3.connection.HTTPSConnection object at 0x7fe6d34bd400>, 'Connection to www.kaggle.com timed out. (connect timeout=5)'))
